Traceback (most recent call last):
  File "/home/x4vyjm/tradexbot/dataAPP/main.py", line 2, in <module>
    from getData import saveData
  File "/home/x4vyjm/tradexbot/dataAPP/getData.py", line 12, in <module>
    class saveData:
  File "/home/x4vyjm/tradexbot/dataAPP/getData.py", line 16, in saveData
    binanceClient = Client()    
  File "/home/x4vyjm/tradexbot/tradexbot/lib/python3.9/site-packages/binance/client.py", line 300, in __init__
    self.ping()
  File "/home/x4vyjm/tradexbot/tradexbot/lib/python3.9/site-packages/binance/client.py", line 526, in ping
    return self._get('ping', version=self.PRIVATE_API_VERSION)
  File "/home/x4vyjm/tradexbot/tradexbot/lib/python3.9/site-packages/binance/client.py", line 371, in _get
    return self._request_api('get', path, signed, version, **kwargs)
  File "/home/x4vyjm/tradexbot/tradexbot/lib/python3.9/site-packages/binance/client.py", line 334, in _request_api
    return self._request(method, uri, signed, **kwargs)
  File "/home/x4vyjm/tradexbot/tradexbot/lib/python3.9/site-packages/binance/client.py", line 315, in _request
    return self._handle_response(self.response)
  File "/home/x4vyjm/tradexbot/tradexbot/lib/python3.9/site-packages/binance/client.py", line 324, in _handle_response
    raise BinanceAPIException(response, response.status_code, response.text)
binance.exceptions.BinanceAPIException: APIError(code=0): Service unavailable from a restricted location according to 'b. Eligibility' in https://www.binance.com/en/terms. Please contact customer service if you believe you received this message in error.
